test_gpu.txt
WARNING:tensorflow:From /homes/es314/miniconda3/envs/tf2_env/lib/python3.8/site-packages/tensorflow/python/ops/resource_variable_ops.py:1659: calling BaseResourceVariable.__init__ (from tensorflow.python.ops.resource_variable_ops) with constraint is deprecated and will be removed in a future version.
Instructions for updating:
If using Keras pass *_constraint arguments to layers.
2023-07-20 18:36:03.025575: I tensorflow/stream_executor/platform/default/dso_loader.cc:44] Successfully opened dynamic library libcuda.so.1
2023-07-20 18:36:04.806807: I tensorflow/core/common_runtime/gpu/gpu_device.cc:1561] Found device 0 with properties: 
pciBusID: 0000:1a:00.0 name: NVIDIA RTX A5000 computeCapability: 8.6
coreClock: 1.695GHz coreCount: 64 deviceMemorySize: 23.69GiB deviceMemoryBandwidth: 715.34GiB/s
2023-07-20 18:36:04.812187: I tensorflow/core/common_runtime/gpu/gpu_device.cc:1561] Found device 1 with properties: 
pciBusID: 0000:1b:00.0 name: NVIDIA RTX A5000 computeCapability: 8.6
coreClock: 1.695GHz coreCount: 64 deviceMemorySize: 23.69GiB deviceMemoryBandwidth: 715.34GiB/s
2023-07-20 18:36:04.812868: I tensorflow/stream_executor/platform/default/dso_loader.cc:44] Successfully opened dynamic library libcudart.so.10.1
2023-07-20 18:36:04.815385: I tensorflow/stream_executor/platform/default/dso_loader.cc:44] Successfully opened dynamic library libcublas.so.10
2023-07-20 18:36:04.817423: I tensorflow/stream_executor/platform/default/dso_loader.cc:44] Successfully opened dynamic library libcufft.so.10
2023-07-20 18:36:04.818038: I tensorflow/stream_executor/platform/default/dso_loader.cc:44] Successfully opened dynamic library libcurand.so.10
2023-07-20 18:36:04.820671: I tensorflow/stream_executor/platform/default/dso_loader.cc:44] Successfully opened dynamic library libcusolver.so.10
2023-07-20 18:36:04.822895: I tensorflow/stream_executor/platform/default/dso_loader.cc:44] Successfully opened dynamic library libcusparse.so.10
2023-07-20 18:36:04.827979: I tensorflow/stream_executor/platform/default/dso_loader.cc:44] Successfully opened dynamic library libcudnn.so.7
2023-07-20 18:36:04.850199: I tensorflow/core/common_runtime/gpu/gpu_device.cc:1703] Adding visible gpu devices: 0, 1
2023-07-20 18:36:08.564364: I tensorflow/core/platform/cpu_feature_guard.cc:143] Your CPU supports instructions that this TensorFlow binary was not compiled to use: AVX2 AVX512F FMA
2023-07-20 18:36:08.583113: I tensorflow/core/platform/profile_utils/cpu_utils.cc:102] CPU Frequency: 2100000000 Hz
2023-07-20 18:36:08.594499: I tensorflow/compiler/xla/service/service.cc:168] XLA service 0x1212f510 initialized for platform Host (this does not guarantee that XLA will be used). Devices:
2023-07-20 18:36:08.595268: I tensorflow/compiler/xla/service/service.cc:176]   StreamExecutor device (0): Host, Default Version
2023-07-20 18:36:11.276849: I tensorflow/compiler/xla/service/service.cc:168] XLA service 0x619e470 initialized for platform CUDA (this does not guarantee that XLA will be used). Devices:
2023-07-20 18:36:11.276919: I tensorflow/compiler/xla/service/service.cc:176]   StreamExecutor device (0): NVIDIA RTX A5000, Compute Capability 8.6
2023-07-20 18:36:11.276928: I tensorflow/compiler/xla/service/service.cc:176]   StreamExecutor device (1): NVIDIA RTX A5000, Compute Capability 8.6
2023-07-20 18:36:11.324733: I tensorflow/core/common_runtime/gpu/gpu_device.cc:1561] Found device 0 with properties: 
pciBusID: 0000:1a:00.0 name: NVIDIA RTX A5000 computeCapability: 8.6
coreClock: 1.695GHz coreCount: 64 deviceMemorySize: 23.69GiB deviceMemoryBandwidth: 715.34GiB/s
2023-07-20 18:36:11.362505: I tensorflow/core/common_runtime/gpu/gpu_device.cc:1561] Found device 1 with properties: 
pciBusID: 0000:1b:00.0 name: NVIDIA RTX A5000 computeCapability: 8.6
coreClock: 1.695GHz coreCount: 64 deviceMemorySize: 23.69GiB deviceMemoryBandwidth: 715.34GiB/s
2023-07-20 18:36:11.362646: I tensorflow/stream_executor/platform/default/dso_loader.cc:44] Successfully opened dynamic library libcudart.so.10.1
2023-07-20 18:36:11.362664: I tensorflow/stream_executor/platform/default/dso_loader.cc:44] Successfully opened dynamic library libcublas.so.10
2023-07-20 18:36:11.362688: I tensorflow/stream_executor/platform/default/dso_loader.cc:44] Successfully opened dynamic library libcufft.so.10
2023-07-20 18:36:11.362704: I tensorflow/stream_executor/platform/default/dso_loader.cc:44] Successfully opened dynamic library libcurand.so.10
2023-07-20 18:36:11.362717: I tensorflow/stream_executor/platform/default/dso_loader.cc:44] Successfully opened dynamic library libcusolver.so.10
2023-07-20 18:36:11.362733: I tensorflow/stream_executor/platform/default/dso_loader.cc:44] Successfully opened dynamic library libcusparse.so.10
2023-07-20 18:36:11.362747: I tensorflow/stream_executor/platform/default/dso_loader.cc:44] Successfully opened dynamic library libcudnn.so.7
2023-07-20 18:36:12.089440: I tensorflow/core/common_runtime/gpu/gpu_device.cc:1703] Adding visible gpu devices: 0, 1
2023-07-20 18:36:12.089598: I tensorflow/stream_executor/platform/default/dso_loader.cc:44] Successfully opened dynamic library libcudart.so.10.1
2023-07-20 18:36:12.438690: I tensorflow/core/common_runtime/gpu/gpu_device.cc:1102] Device interconnect StreamExecutor with strength 1 edge matrix:
2023-07-20 18:36:12.438750: I tensorflow/core/common_runtime/gpu/gpu_device.cc:1108]      0 1 
2023-07-20 18:36:12.438765: I tensorflow/core/common_runtime/gpu/gpu_device.cc:1121] 0:   N Y 
2023-07-20 18:36:12.438772: I tensorflow/core/common_runtime/gpu/gpu_device.cc:1121] 1:   Y N 
2023-07-20 18:36:12.518447: I tensorflow/core/common_runtime/gpu/gpu_device.cc:1247] Created TensorFlow device (/job:localhost/replica:0/task:0/device:GPU:0 with 22610 MB memory) -> physical GPU (device: 0, name: NVIDIA RTX A5000, pci bus id: 0000:1a:00.0, compute capability: 8.6)
2023-07-20 18:36:12.535485: I tensorflow/core/common_runtime/gpu/gpu_device.cc:1247] Created TensorFlow device (/job:localhost/replica:0/task:0/device:GPU:1 with 22610 MB memory) -> physical GPU (device: 1, name: NVIDIA RTX A5000, pci bus id: 0000:1b:00.0, compute capability: 8.6)
/homes/es314/miniconda3/envs/tf2_env/bin/python3
Weights:  coco
Logs:  /homes/es314/pitch_Mask_RCNN/logs

Configurations:
BACKBONE                       resnet101
BACKBONE_STRIDES               [4, 8, 16, 32, 64]
BATCH_SIZE                     1
BBOX_STD_DEV                   [0.1 0.1 0.2 0.2]
COMPUTE_BACKBONE_SHAPE         None
DETECTION_MAX_INSTANCES        100
DETECTION_MIN_CONFIDENCE       0.9
DETECTION_NMS_THRESHOLD        0.3
FPN_CLASSIF_FC_LAYERS_SIZE     1024
GPU_COUNT                      1
GRADIENT_CLIP_NORM             5.0
IMAGES_PER_GPU                 1
IMAGE_CHANNEL_COUNT            3
IMAGE_MAX_DIM                  1024
IMAGE_META_SIZE                63
IMAGE_MIN_DIM                  800
IMAGE_MIN_SCALE                0
IMAGE_RESIZE_MODE              square
IMAGE_SHAPE                    [1024 1024    3]
LEARNING_MOMENTUM              0.9
LEARNING_RATE                  0.001
LOSS_WEIGHTS                   {'rpn_class_loss': 1.0, 'rpn_bbox_loss': 1.0, 'mrcnn_class_loss': 1.0, 'mrcnn_bbox_loss': 1.0, 'mrcnn_mask_loss': 1.0}
MASK_POOL_SIZE                 14
MASK_SHAPE                     [28, 28]
MAX_GT_INSTANCES               100
MEAN_PIXEL                     [123.7 116.8 103.9]
MINI_MASK_SHAPE                (56, 56)
NAME                           Doremi
NUM_CLASSES                    51
POOL_SIZE                      7
POST_NMS_ROIS_INFERENCE        1000
POST_NMS_ROIS_TRAINING         2000
PRE_NMS_LIMIT                  6000
ROI_POSITIVE_RATIO             0.33
RPN_ANCHOR_RATIOS              [0.5, 1, 2]
RPN_ANCHOR_SCALES              (32, 64, 128, 256, 512)
RPN_ANCHOR_STRIDE              1
RPN_BBOX_STD_DEV               [0.1 0.1 0.2 0.2]
RPN_NMS_THRESHOLD              0.7
RPN_TRAIN_ANCHORS_PER_IMAGE    256
STEPS_PER_EPOCH                100
TOP_DOWN_PYRAMID_SIZE          256
TRAIN_BN                       False
